<?xml version="1.0" ?>
<!-- =================================================================================== -->
<!-- |    This document was autogenerated by xacro from simple_rover.urdf.xacro        | -->
<!-- |    EDITING THIS FILE BY HAND IS NOT RECOMMENDED                                 | -->
<!-- =================================================================================== -->
<robot name="simple_rover" xmlns:xacro="http://www.ros.org/wiki/xacro">
  <!-- Links -->
  <link name="base_link">
    <visual>
      <origin xyz="0 0 0"/>
      <geometry>
        <box size="1 0.5 0.1"/>
      </geometry>
    </visual>
  </link>
  <link name="wheel_right_front_link">
    <!-- inertial></inertial -->
    <visual>
      <!--origin xyz="${xyz}" rpy="${wheel_rpy}"/ -->
      <geometry>
        <cylinder length="0.1" radius="0.25"/>
      </geometry>
    </visual>
    <!-- collision></collision -->
  </link>
  <joint name="wheel_right_front_joint" type="continuous">
    <origin rpy="-1.57079632679 0 0" xyz="0.4 -0.3 0"/>
    <parent link="base_link"/>
    <child link="wheel_right_front_link"/>
    <axis xyz="0 0 1"/>
  </joint>
  <transmission name="wheel_right_front_trans">
    <type>transmission_interface/SimpleTransmission</type>
    <joint name="wheel_right_front_joint">
      <hardwareInterface>EffortJointInterface</hardwareInterface>
    </joint>
    <actuator name="wheel_right_front_motor">
      <mechanicalReduction>1</mechanicalReduction>
      <!-- hardwareInterface>EffortJointInterface</hardwareInterface -->
    </actuator>
  </transmission>
  <link name="wheel_right_back_link">
    <!-- inertial></inertial -->
    <visual>
      <!--origin xyz="${xyz}" rpy="${wheel_rpy}"/ -->
      <geometry>
        <cylinder length="0.1" radius="0.25"/>
      </geometry>
    </visual>
    <!-- collision></collision -->
  </link>
  <joint name="wheel_right_back_joint" type="continuous">
    <origin rpy="-1.57079632679 0 0" xyz="-0.4 -0.3 0"/>
    <parent link="base_link"/>
    <child link="wheel_right_back_link"/>
    <axis xyz="0 0 1"/>
  </joint>
  <transmission name="wheel_right_back_trans">
    <type>transmission_interface/SimpleTransmission</type>
    <joint name="wheel_right_back_joint">
      <hardwareInterface>EffortJointInterface</hardwareInterface>
    </joint>
    <actuator name="wheel_right_back_motor">
      <mechanicalReduction>1</mechanicalReduction>
      <!-- hardwareInterface>EffortJointInterface</hardwareInterface -->
    </actuator>
  </transmission>
  <link name="wheel_left_front_link">
    <!-- inertial></inertial -->
    <visual>
      <!--origin xyz="${xyz}" rpy="${wheel_rpy}"/ -->
      <geometry>
        <cylinder length="0.1" radius="0.25"/>
      </geometry>
    </visual>
    <!-- collision></collision -->
  </link>
  <joint name="wheel_left_front_joint" type="continuous">
    <origin rpy="-1.57079632679 0 0" xyz="0.4 0.3 0"/>
    <parent link="base_link"/>
    <child link="wheel_left_front_link"/>
    <axis xyz="0 0 1"/>
  </joint>
  <transmission name="wheel_left_front_trans">
    <type>transmission_interface/SimpleTransmission</type>
    <joint name="wheel_left_front_joint">
      <hardwareInterface>EffortJointInterface</hardwareInterface>
    </joint>
    <actuator name="wheel_left_front_motor">
      <mechanicalReduction>1</mechanicalReduction>
      <!-- hardwareInterface>EffortJointInterface</hardwareInterface -->
    </actuator>
  </transmission>
  <link name="wheel_left_back_link">
    <!-- inertial></inertial -->
    <visual>
      <!--origin xyz="${xyz}" rpy="${wheel_rpy}"/ -->
      <geometry>
        <cylinder length="0.1" radius="0.25"/>
      </geometry>
    </visual>
    <!-- collision></collision -->
  </link>
  <joint name="wheel_left_back_joint" type="continuous">
    <origin rpy="-1.57079632679 0 0" xyz="-0.4 0.3 0"/>
    <parent link="base_link"/>
    <child link="wheel_left_back_link"/>
    <axis xyz="0 0 1"/>
  </joint>
  <transmission name="wheel_left_back_trans">
    <type>transmission_interface/SimpleTransmission</type>
    <joint name="wheel_left_back_joint">
      <hardwareInterface>EffortJointInterface</hardwareInterface>
    </joint>
    <actuator name="wheel_left_back_motor">
      <mechanicalReduction>1</mechanicalReduction>
      <!-- hardwareInterface>EffortJointInterface</hardwareInterface -->
    </actuator>
  </transmission>
  <gazebo>
    <plugin filename="libgazebo_ros_control.so" name="gazebo_ros_control">
    </plugin>
  </gazebo>
</robot>

